Workbook

Sheet Read Me
A1: APC40 mkII Electric Zentropa True Button Toggles Map
A2: Accepted Resolume Avenue 7.27.1 mapping — one physical control per layer, with all 203 XML shortcuts exposed
A3: NOTE: In the True Button Toggles layout, physical Note buttons utilize Resolume's native toggle behaviors.
A4: This provides full physical LED color toggles on the controller, at the expense of potential desyncs with the on-screen UI. | B4: Value | D4: Latest saved visual language
A5: Composition | B5: APC40_Visual_QA_148 | D5: Role | E5: Witness | F5: Color | G5: Meaning | H5: State authority
A6: Accepted build | B6: B1-728792218d26e596 | D6: Grid | E6: G1-1 … G8-5 | F6: Column RGB | G6: Physical pad column | H6: MIDI
A7: Preset | B7: APC 40 MK II - Visual QA | D7: Fixed buttons | E7: Labels | F7: Amber / white | G7: Device LED family | H7: MIDI
A8: Preset ID | B8: 2027461064 | D8: Solo | E8: S | F8: Blue | G8: Dedicated Solo LED | H8: MIDI
A9: Resolume version | B9: 7.27.1.15990 | D9: Record Arm | E9: ● | F9: Red | G9: Dedicated Record Arm LED | H9: MIDI
A10: Source XML | B10: controllers/APC 40 MK II - Visual QA.xml | D10: Continuous | E10: Faders / knobs | F10: White; Tempo red | G10: No colored LED; Tempo is relative | H10: MIDI + value
A11: Source SHA-256 | B11: 4628634b4fb9a9909a5b1ee9d7c9df1a759371cc7a90ce183d8bb4cc40d1abc5
A12: Source modified | B12: 46222.36 | D12: Workbook tabs
A13: Physical controls | B13: =COUNTA('Control Map'!$A$5:$A$152) | D13: Control Map | E13: 148 physical controls | F13: layout, color, MIDI | G13: mapping count | H13: row QA
A14: XML shortcut records | B14: =COUNTA('XML Shortcuts'!$B$5:$B$207) | D14: XML Shortcuts | E14: 203 XML records | F14: paths and IDs | G14: ranges | H14: feedback
A15: Unique raw MIDI keys | B15: =ROWS(_xlfn.UNIQUE('XML Shortcuts'!$J$5:$J$207)) | D15: Continuous Detail | E15: 28 CC controls | F15: wake | G15: opacity | H15: motion
A16: Buttons / notes | B16: =COUNTIF('Control Map'!$E$5:$E$152,"note") | D16: Button Feedback | E16: 120 notes | F16: connect path | G16: LED velocity | H16: feedback
A17: Continuous controls / CC | B17: =COUNTIF('Control Map'!$E$5:$E$152,"cc") | D17: QA Checks | E17: contract tests | F17: formula-driven | G17: expected vs actual | H17: PASS / FAIL

Sheet Control Map
A1: Physical Control Map — 148 Controls
A2: The manifest joins each hardware control to its layer, Text Animator witness, raw MIDI key, and accepted XML roles
A4: Layer | B4: Section | C4: Label | D4: Layer Name | E4: MIDI Type | F4: Data 1 | G4: Channel | H4: MIDI Address | I4: Raw Key | J4: LED Velocity | K4: Witness Color | L4: Panel X | M4: Panel Y | N4: Avenue X | O4: Avenue Y | P4: Scale % | Q4: Expected Clip Name | R4: Mapping Count | S4: XML Roles | T4: QA
A5: 1 | B5: grid | C5: G1-5 | D5: Grid 5 Track 1 | E5: note | F5: 0 | G5: 1 | H5: N0/C1 | I5: 72057594037928080 | J5: 45 | K5: #2b5bffff | L5: 225 | M5: 1085 | N5: -769 | O5: -68 | P5: 50 | Q5: N0/C1 | R5: 1 | S5: button_connect | T5: PASS
A6: 2 | B6: grid | C6: G2-5 | D6: Grid 5 Track 2 | E6: note | F6: 1 | G6: 1 | H6: N1/C1 | I6: 72057594037928336 | J6: 37 | K6: #17c8e8ff | L6: 545 | M6: 1085 | N6: -639 | O6: -68 | P6: 50 | Q6: N1/C1 | R6: 1 | S6: button_connect | T6: PASS
A7: 3 | B7: grid | C7: G3-5 | D7: Grid 5 Track 3 | E7: note | F7: 2 | G7: 1 | H7: N2/C1 | I7: 72057594037928592 | J7: 21 | K7: #23c552ff | L7: 865 | M7: 1085 | N7: -509 | O7: -68 | P7: 50 | Q7: N2/C1 | R7: 1 | S7: button_connect | T7: PASS
A8: 4 | B8: grid | C8: G4-5 | D8: Grid 5 Track 4 | E8: note | F8: 3 | G8: 1 | H8: N3/C1 | I8: 72057594037928848 | J8: 5 | K8: #e23b3bff | L8: 1185 | M8: 1085 | N8: -379 | O8: -68 | P8: 50 | Q8: N3/C1 | R8: 1 | S8: button_connect | T8: PASS
A9: 5 | B9: grid | C9: G5-5 | D9: Grid 5 Track 5 | E9: note | F9: 4 | G9: 1 | H9: N4/C1 | I9: 72057594037929104 | J9: 9 | K9: #f08a24ff | L9: 1505 | M9: 1085 | N9: -249 | O9: -68 | P9: 50 | Q9: N4/C1 | R9: 1 | S9: button_connect | T9: PASS
A10: 6 | B10: grid | C10: G6-5 | D10: Grid 5 Track 6 | E10: note | F10: 5 | G10: 1 | H10: N5/C1 | I10: 72057594037929360 | J10: 49 | K10: #7a3fc0ff | L10: 1825 | M10: 1085 | N10: -120 | O10: -68 | P10: 50 | Q10: N5/C1 | R10: 1 | S10: button_connect | T10: PASS
A11: 7 | B11: grid | C11: G7-5 | D11: Grid 5 Track 7 | E11: note | F11: 6 | G11: 1 | H11: N6/C1 | I11: 72057594037929616 | J11: 53 | K11: #c81e9aff | L11: 2145 | M11: 1085 | N11: 10 | O11: -68 | P11: 50 | Q11: N6/C1 | R11: 1 | S11: button_connect | T11: PASS
A12: 8 | B12: grid | C12: G8-5 | D12: Grid 5 Track 8 | E12: note | F12: 7 | G12: 1 | H12: N7/C1 | I12: 72057594037929872 | J12: 3 | K12: #e6e6e6ff | L12: 2465 | M12: 1085 | N12: 140 | O12: -68 | P12: 50 | Q12: N7/C1 | R12: 1 | S12: button_connect | T12: PASS
A13: 9 | B13: grid | C13: G1-4 | D13: Grid 4 Track 1 | E13: note | F13: 8 | G13: 1 | H13: N8/C1 | I13: 72057594037930128 | J13: 45 | K13: #2b5bffff | L13: 225 | M13: 930 | N13: -769 | O13: -128 | P13: 50 | Q13: N8/C1 | R13: 1 | S13: button_connect | T13: PASS
A14: 10 | B14: grid | C14: G2-4 | D14: Grid 4 Track 2 | E14: note | F14: 9 | G14: 1 | H14: N9/C1 | I14: 72057594037930384 | J14: 37 | K14: #17c8e8ff | L14: 545 | M14: 930 | N14: -639 | O14: -128 | P14: 50 | Q14: N9/C1 | R14: 1 | S14: button_connect | T14: PASS
A15: 11 | B15: grid | C15: G3-4 | D15: Grid 4 Track 3 | E15: note | F15: 10 | G15: 1 | H15: N10/C1 | I15: 72057594037930640 | J15: 21 | K15: #23c552ff | L15: 865 | M15: 930 | N15: -509 | O15: -128 | P15: 50 | Q15: N10/C1 | R15: 1 | S15: button_connect | T15: PASS
A16: 12 | B16: grid | C16: G4-4 | D16: Grid 4 Track 4 | E16: note | F16: 11 | G16: 1 | H16: N11/C1 | I16: 72057594037930896 | J16: 5 | K16: #e23b3bff | L16: 1185 | M16: 930 | N16: -379 | O16: -128 | P16: 50 | Q16: N11/C1 | R16: 1 | S16: button_connect | T16: PASS
... A152: 148 | B152: tempo | C152: TEMPO | D152: Tempo Knob | E152: cc | F152: 13 | G152: 1 | H152: CC13/C1 | I152: 144115188075859376 | J152: 0 | K152: #e23b3bff | L152: 4010 | M152: 650 | N152: 767 | O152: -237 | P152: 28 | Q152: CC13/C1 | R152: 2 | S152: wake, tempo_motion | T152: PASS

Sheet XML Shortcuts
A1: Accepted XML Shortcut Stream — 203 Records
A2: Source SHA-256 4628634b4fb9a9909a5b1ee9d7c9df1a759371cc7a90ce183d8bb4cc40d1abc5 — record order preserved exactly as installed
A4: Order | B4: Unique ID | C4: Role | D4: Layer | E4: Control | F4: Layer Name | G4: MIDI Type | H4: Data 1 | I4: Channel | J4: Raw Key | K4: MIDI Address | L4: Input Path | M4: Behaviour | N4: Input Mode | O4: Range Min | P4: Range Max | Q4: Direction | R4: Num Steps | S4: Raw Value | T4: Output Device | U4: Output Path | V4: Input Sibling | W4: Output Sibling | X4: Named Values
A5: 1 | B5: 1784313900056 | C5: button_connect | D5: 56 | E5: SEL3 | F5: Track Select 3 | G5: note | H5: 51 | I5: 3 | J5: 72057594037941138 | K5: N51/C3 | L5: /composition/layers/56/clips/1/connect | M5: 1028 | N5: Button / value | R5: 128 | S5: 0 | T5: APC40 mkII | U5: /composition/layers/56/clips/1/connect | V5: /composition/layers/56/clips/1/connected | W5: /composition/layers/56/clips/1/connected | X5: Connected=0.35433070866141730404; Connected & previewing=0.35433070866141730404; Disconnected=0; Empty=0; Off=0; Previewing=0
A6: 2 | B6: 1784313900001 | C6: button_connect | D6: 1 | E6: G1-5 | F6: Grid 5 Track 1 | G6: note | H6: 0 | I6: 1 | J6: 72057594037928080 | K6: N0/C1 | L6: /composition/layers/1/clips/1/connect | M6: 1028 | N6: Button / value | R6: 128 | S6: 0 | T6: APC40 mkII | U6: /composition/layers/1/clips/1/connect | V6: /composition/layers/1/clips/1/connected | W6: /composition/layers/1/clips/1/connected | X6: Connected=0.35433070866141730404; Connected & previewing=0.35433070866141730404; Disconnected=0; Empty=0; Off=0; Previewing=0
A7: 3 | B7: 1784313900042 | C7: button_connect | D7: 42 | E7: SCENE2 | F7: Scene Launch 2 | G7: note | H7: 83 | I7: 1 | J7: 72057594037949328 | K7: N83/C1 | L7: /composition/layers/42/clips/1/connect | M7: 1028 | N7: Button / value | R7: 128 | S7: 0 | T7: APC40 mkII | U7: /composition/layers/42/clips/1/connect | V7: /composition/layers/42/clips/1/connected | W7: /composition/layers/42/clips/1/connected | X7: Connected=0.16535433070866142891; Connected & previewing=0.16535433070866142891; Disconnected=0; Empty=0; Off=0; Previewing=0
A8: 4 | B8: 1784313900041 | C8: button_connect | D8: 41 | E8: SCENE1 | F8: Scene Launch 1 | G8: note | H8: 82 | I8: 1 | J8: 72057594037949072 | K8: N82/C1 | L8: /composition/layers/41/clips/1/connect | M8: 1028 | N8: Button / value | R8: 128 | S8: 0 | T8: APC40 mkII | U8: /composition/layers/41/clips/1/connect | V8: /composition/layers/41/clips/1/connected | W8: /composition/layers/41/clips/1/connected | X8: Connected=0.16535433070866142891; Connected & previewing=0.16535433070866142891; Disconnected=0; Empty=0; Off=0; Previewing=0
A9: 5 | B9: 1784313900007 | C9: button_connect | D9: 7 | E9: G7-5 | F9: Grid 5 Track 7 | G9: note | H9: 6 | I9: 1 | J9: 72057594037929616 | K9: N6/C1 | L9: /composition/layers/7/clips/1/connect | M9: 1028 | N9: Button / value | R9: 128 | S9: 0 | T9: APC40 mkII | U9: /composition/layers/7/clips/1/connect | V9: /composition/layers/7/clips/1/connected | W9: /composition/layers/7/clips/1/connected | X9: Connected=0.41732283464566927167; Connected & previewing=0.41732283464566927167; Disconnected=0; Empty=0; Off=0; Previewing=0
A10: 6 | B10: 1784313900005 | C10: button_connect | D10: 5 | E10: G5-5 | F10: Grid 5 Track 5 | G10: note | H10: 4 | I10: 1 | J10: 72057594037929104 | K10: N4/C1 | L10: /composition/layers/5/clips/1/connect | M10: 1028 | N10: Button / value | R10: 128 | S10: 0 | T10: APC40 mkII | U10: /composition/layers/5/clips/1/connect | V10: /composition/layers/5/clips/1/connected | W10: /composition/layers/5/clips/1/connected | X10: Connected=0.070866141732283463583; Connected & previewing=0.070866141732283463583; Disconnected=0; Empty=0; Off=0; Previewing=0
A11: 7 | B11: 1784313900046 | C11: button_connect | D11: 46 | E11: STOP1 | F11: Clip Stop 1 | G11: note | H11: 52 | I11: 1 | J11: 72057594037941392 | K11: N52/C1 | L11: /composition/layers/46/clips/1/connect | M11: 1028 | N11: Button / value | R11: 128 | S11: 0 | T11: APC40 mkII | U11: /composition/layers/46/clips/1/connect | V11: /composition/layers/46/clips/1/connected | W11: /composition/layers/46/clips/1/connected | X11: Connected=0.039370078740157479769; Connected & previewing=0.039370078740157479769; Disconnected=0; Empty=0; Off=0; Previewing=0
A12: 8 | B12: 1784313900023 | C12: button_connect | D12: 23 | E12: G7-3 | F12: Grid 3 Track 7 | G12: note | H12: 22 | I12: 1 | J12: 72057594037933712 | K12: N22/C1 | L12: /composition/layers/23/clips/1/connect | M12: 1028 | N12: Button / value | R12: 128 | S12: 0 | T12: APC40 mkII | U12: /composition/layers/23/clips/1/connect | V12: /composition/layers/23/clips/1/connected | W12: /composition/layers/23/clips/1/connected | X12: Connected=0.41732283464566927167; Connected & previewing=0.41732283464566927167; Disconnected=0; Empty=0; Off=0; Previewing=0
A13: 9 | B13: 1784313900050 | C13: button_connect | D13: 50 | E13: STOP5 | F13: Clip Stop 5 | G13: note | H13: 52 | I13: 5 | J13: 72057594037941396 | K13: N52/C5 | L13: /composition/layers/50/clips/1/connect | M13: 1028 | N13: Button / value | R13: 128 | S13: 0 | T13: APC40 mkII | U13: /composition/layers/50/clips/1/connect | V13: /composition/layers/50/clips/1/connected | W13: /composition/layers/50/clips/1/connected | X13: Connected=0.039370078740157479769; Connected & previewing=0.039370078740157479769; Disconnected=0; Empty=0; Off=0; Previewing=0
A14: 10 | B14: 1784313900024 | C14: button_connect | D14: 24 | E14: G8-3 | F14: Grid 3 Track 8 | G14: note | H14: 23 | I14: 1 | J14: 72057594037933968 | K14: N23/C1 | L14: /composition/layers/24/clips/1/connect | M14: 1028 | N14: Button / value | R14: 128 | S14: 0 | T14: APC40 mkII | U14: /composition/layers/24/clips/1/connect | V14: /composition/layers/24/clips/1/connected | W14: /composition/layers/24/clips/1/connected | X14: Connected=0.023622047244094487861; Connected & previewing=0.023622047244094487861; Disconnected=0; Empty=0; Off=0; Previewing=0
A15: 11 | B15: 1784313900044 | C15: button_connect | D15: 44 | E15: SCENE4 | F15: Scene Launch 4 | G15: note | H15: 85 | I15: 1 | J15: 72057594037949840 | K15: N85/C1 | L15: /composition/layers/44/clips/1/connect | M15: 1028 | N15: Button / value | R15: 128 | S15: 0 | T15: APC40 mkII | U15: /composition/layers/44/clips/1/connect | V15: /composition/layers/44/clips/1/connected | W15: /composition/layers/44/clips/1/connected | X15: Connected=0.16535433070866142891; Connected & previewing=0.16535433070866142891; Disconnected=0; Empty=0; Off=0; Previewing=0
A16: 12 | B16: 1784313900013 | C16: button_connect | D16: 13 | E16: G5-4 | F16: Grid 4 Track 5 | G16: note | H16: 12 | I16: 1 | J16: 72057594037931152 | K16: N12/C1 | L16: /composition/layers/13/clips/1/connect | M16: 1028 | N16: Button / value | R16: 128 | S16: 0 | T16: APC40 mkII | U16: /composition/layers/13/clips/1/connect | V16: /composition/layers/13/clips/1/connected | W16: /composition/layers/13/clips/1/connected | X16: Connected=0.070866141732283463583; Connected & previewing=0.070866141732283463583; Disconnected=0; Empty=0; Off=0; Previewing=0
... A69: 65 | B69: 1784313900004 | C69: button_connect | D69: 4 | E69: G4-5 | F69: Grid 5 Track 4 | G69: note | H69: 3 | I69: 1 | J69: 72057594037928848 | K69: N3/C1 | L69: /composition/layers/4/clips/1/connect | M69: 1028 | N69: Button / value | R69: 128 | S69: 0 | T69: APC40 mkII | U69: /composition/layers/4/clips/1/connect | V69: /composition/layers/4/clips/1/connected | W69: /composition/layers/4/clips/1/connected | X69: Connected=0.039370078740157479769; Connected & previewing=0.039370078740157479769; Disconnected=0; Empty=0; Off=0; Previewing=0
A70: 66 | B70: 1784313901145 | C70: wake | D70: 145 | E70: CUE | F70: Cue Level | G70: cc | H70: 47 | I70: 1 | J70: 144115188075868080 | K70: CC47/C1 | L70: /composition/layers/145/clips/1/connect | M70: 1028 | N70: CC wake | R70: 128 | S70: 1 | U70: /composition/layers/145/clips/1/connect | X70: Disconnected=1
A71: 67 | B71: 1784313900145 | C71: opacity | D71: 145 | E71: CUE | F71: Cue Level | G71: cc | H71: 47 | I71: 1 | J71: 144115188075868080 | K71: CC47/C1 | L71: /composition/layers/145/clips/1/video/opacity | M71: 8 | N71: Absolute | O71: 0.35 | P71: 1 | Q71: ascending | R71: 128 | S71: 1 | U71: /composition/layers/145/clips/1/video/opacity
A72: 68 | B72: 1784313902145 | C72: motion_rotation | D72: 145 | E72: CUE | F72: Cue Level | G72: cc | H72: 47 | I72: 1 | J72: 144115188075868080 | K72: CC47/C1 | L72: /composition/layers/145/clips/1/video/effects/transform/rotationz | M72: 8 | N72: Absolute | O72: 0.125 | P72: 0.875 | Q72: ascending | R72: 128 | S72: 1 | U72: /composition/layers/145/clips/1/video/effects/transform/rotationz
A73: 69 | B73: 1784313901148 | C73: wake | D73: 148 | E73: TEMPO | F73: Tempo Knob | G73: cc | H73: 13 | I73: 1 | J73: 144115188075859376 | K73: CC13/C1 | L73: /composition/layers/148/clips/1/connect | M73: 1028 | N73: CC wake | R73: 128 | S73: 1 | U73: /composition/layers/148/clips/1/connect | X73: Disconnected=1
A74: 70 | B74: 1784313900148 | C74: tempo_motion | D74: 148 | E74: TEMPO | F74: Tempo Knob | G74: cc | H74: 13 | I74: 1 | J74: 144115188075859376 | K74: CC13/C1 | L74: /composition/layers/148/clips/1/video/effects/transform/rotationz | M74: 16392 | N74: Relative | Q74: relative | R74: 480 | S74: -0.0020833333 | U74: /composition/layers/148/clips/1/video/effects/transform/rotationz
A75: 71 | B75: 1784313900067 | C75: button_connect | D75: 67 | E75: ● | F75: Record Arm 6 | G75: note | H75: 48 | I75: 6 | J75: 72057594037940373 | K75: N48/C6 | L75: /composition/layers/67/clips/1/connect | M75: 1028 | N75: Button / value | R75: 128 | S75: 0 | T75: APC40 mkII | U75: /composition/layers/67/clips/1/connect | V75: /composition/layers/67/clips/1/connected | W75: /composition/layers/67/clips/1/connected | X75: Connected=0.039370078740157479769; Connected & previewing=0.039370078740157479769; Disconnected=0; Empty=0; Off=0; Previewing=0
A76: 72 | B76: 1784313901094 | C76: wake | D76: 94 | E76: FADER1 | F76: Track Fader 1 | G76: cc | H76: 7 | I76: 1 | J76: 144115188075857840 | K76: CC7/C1 | L76: /composition/layers/94/clips/1/connect | M76: 1028 | N76: CC wake | R76: 128 | S76: 1 | U76: /composition/layers/94/clips/1/connect | X76: Disconnected=1
A77: 73 | B77: 1784313900094 | C77: opacity | D77: 94 | E77: FADER1 | F77: Track Fader 1 | G77: cc | H77: 7 | I77: 1 | J77: 144115188075857840 | K77: CC7/C1 | L77: /composition/layers/94/clips/1/video/opacity | M77: 8 | N77: Absolute | O77: 0.65 | P77: 1 | Q77: ascending | R77: 128 | S77: 1 | U77: /composition/layers/94/clips/1/video/opacity
A78: 74 | B78: 1784313902094 | C78: motion_y | D78: 94 | E78: FADER1 | F78: Track Fader 1 | G78: cc | H78: 7 | I78: 1 | J78: 144115188075857840 | K78: CC7/C1 | L78: /composition/layers/94/clips/1/video/effects/transform/positiony | M78: 8 | N78: Absolute | O78: 0.50662994 | P78: 0.50429535 | Q78: descending | R78: 128 | S78: 1 | U78: /composition/layers/94/clips/1/video/effects/transform/positiony
A79: 75 | B79: 1784313900070 | C79: button_connect | D79: 70 | E79: S | F79: Solo 1 | G79: note | H79: 49 | I79: 1 | J79: 72057594037940624 | K79: N49/C1 | L79: /composition/layers/70/clips/1/connect | M79: 1028 | N79: Button / value | R79: 128 | S79: 0 | T79: APC40 mkII | U79: /composition/layers/70/clips/1/connect | V79: /composition/layers/70/clips/1/connected | W79: /composition/layers/70/clips/1/connected | X79: Connected=1; Connected & previewing=1; Disconnected=0; Empty=0; Off=0; Previewing=0
A80: 76 | B80: 1784313900147 | C80: button_connect | D80: 147 | E80: BANKLCK | F80: Bank Lock | G80: note | H80: 103 | I80: 1 | J80: 72057594037954448 | K80: N103/C1 | L80: /composition/layers/147/clips/1/connect | M80: 1028 | N80: Button / value | R80: 128 | S80: 0 | T80: APC40 mkII | U80: /composition/layers/147/clips/1/connect | V80: /composition/layers/147/clips/1/connected | W80: /composition/layers/147/clips/1/connected | X80: Connected=0.38582677165354328785; Connected & previewing=0.38582677165354328785; Disconnected=0; Empty=0; Off=0; Previewing=0
A81: 77 | B81: 1784313900140 | C81: button_connect | D81: 140 | E81: USER | F81: User Mode | G81: note | H81: 89 | I81: 1 | J81: 72057594037950864 | K81: N89/C1 | L81: /composition/layers/140/clips/1/connect | M81: 1028 | N81: Button / value | R81: 128 | S81: 0 | T81: APC40 mkII | U81: /composition/layers/140/clips/1/connect | V81: /composition/layers/140/clips/1/connected | W81: /composition/layers/140/clips/1/connected | X81: Connected=0.38582677165354328785; Connected & previewing=0.38582677165354328785; Disconnected=0; Empty=0; Off=0; Previewing=0
A82: 78 | B82: 1784313900082 | C82: button_connect | D82: 82 | E82: 5 | F82: Activator 5 | G82: note | H82: 50 | I82: 5 | J82: 72057594037940884 | K82: N50/C5 | L82: /composition/layers/82/clips/1/connect | M82: 1028 | N82: Button / value | R82: 128 | S82: 0 | T82: APC40 mkII | U82: /composition/layers/82/clips/1/connect | V82: /composition/layers/82/clips/1/connected | W82: /composition/layers/82/clips/1/connected | X82: Connected=0.16535433070866142891; Connected & previewing=0.16535433070866142891; Disconnected=0; Empty=0; Off=0; Previewing=0
A83: 79 | B83: 1784313900090 | C83: button_connect | D83: 90 | E83: A/B | F83: Crossfade A B 5 | G83: note | H83: 66 | I83: 5 | J83: 72057594037944980 | K83: N66/C5 | L83: /composition/layers/90/clips/1/connect | M83: 1028 | N83: Button / value | R83: 128 | S83: 0 | T83: APC40 mkII | U83: /composition/layers/90/clips/1/connect | V83: /composition/layers/90/clips/1/connected | W83: /composition/layers/90/clips/1/connected | X83: Connected=0.070866141732283463583; Connected & previewing=0.070866141732283463583; Disconnected=0; Empty=0; Off=0; Previewing=0
A84: 80 | B84: 1784313900137 | C84: button_connect | D84: 137 | E84: CLIP/DEV | F84: Clip Device View | G84: note | H84: 64 | I84: 1 | J84: 72057594037944464 | K84: N64/C1 | L84: /composition/layers/137/clips/1/connect | M84: 1028 | N84: Button / value | R84: 128 | S84: 0 | T84: APC40 mkII | U84: /composition/layers/137/clips/1/connect | V84: /composition/layers/137/clips/1/connected | W84: /composition/layers/137/clips/1/connected | X84: Connected=0.38582677165354328785; Connected & previewing=0.38582677165354328785; Disconnected=0; Empty=0; Off=0; Previewing=0
A85: 81 | B85: 1784313900138 | C85: button_connect | D85: 138 | E85: DETAIL | F85: Detail View | G85: note | H85: 65 | I85: 1 | J85: 72057594037944720 | K85: N65/C1 | L85: /composition/layers/138/clips/1/connect | M85: 1028 | N85: Button / value | R85: 128 | S85: 0 | T85: APC40 mkII | U85: /composition/layers/138/clips/1/connect | V85: /composition/layers/138/clips/1/connected | W85: /composition/layers/138/clips/1/connected | X85: Connected=0.38582677165354328785; Connected & previewing=0.38582677165354328785; Disconnected=0; Empty=0; Off=0; Previewing=0
A86: 82 | B86: 1784313900072 | C86: button_connect | D86: 72 | E86: S | F86: Solo 3 | G86: note | H86: 49 | I86: 3 | J86: 72057594037940626 | K86: N49/C3 | L86: /composition/layers/72/clips/1/connect | M86: 1028 | N86: Button / value | R86: 128 | S86: 0 | T86: APC40 mkII | U86: /composition/layers/72/clips/1/connect | V86: /composition/layers/72/clips/1/connected | W86: /composition/layers/72/clips/1/connected | X86: Connected=1; Connected & previewing=1; Disconnected=0; Empty=0; Off=0; Previewing=0
A87: 83 | B87: 1784313900142 | C87: button_connect | D87: 142 | E87: SESSION | F87: Session Record | G87: note | H87: 102 | I87: 1 | J87: 72057594037954192 | K87: N102/C1 | L87: /composition/layers/142/clips/1/connect | M87: 1028 | N87: Button / value | R87: 128 | S87: 0 | T87: APC40 mkII | U87: /composition/layers/142/clips/1/connect | V87: /composition/layers/142/clips/1/connected | W87: /composition/layers/142/clips/1/connected | X87: Connected=0.41732283464566927167; Connected & previewing=0.41732283464566927167; Disconnected=0; Empty=0; Off=0; Previewing=0
A88: 84 | B88: 1784313900141 | C88: button_connect | D88: 141 | E88: METRO | F88: Metronome | G88: note | H88: 90 | I88: 1 | J88: 72057594037951120 | K88: N90/C1 | L88: /composition/layers/141/clips/1/connect | M88: 1028 | N88: Button / value | R88: 128 | S88: 0 | T88: APC40 mkII | U88: /composition/layers/141/clips/1/connect | V88: /composition/layers/141/clips/1/connected | W88: /composition/layers/141/clips/1/connected | X88: Connected=0.1023622047244094474; Connected & previewing=0.1023622047244094474; Disconnected=0; Empty=0; Off=0; Previewing=0
A89: 85 | B89: 1784313900092 | C89: button_connect | D89: 92 | E89: A/B | F89: Crossfade A B 7 | G89: note | H89: 66 | I89: 7 | J89: 72057594037944982 | K89: N66/C7 | L89: /composition/layers/92/clips/1/connect | M89: 1028 | N89: Button / value | R89: 128 | S89: 0 | T89: APC40 mkII | U89: /composition/layers/92/clips/1/connect | V89: /composition/layers/92/clips/1/connected | W89: /composition/layers/92/clips/1/connected | X89: Connected=0.070866141732283463583; Connected & previewing=0.070866141732283463583; Disconnected=0; Empty=0; Off=0; Previewing=0
A90: 86 | B90: 1784313900071 | C90: button_connect | D90: 71 | E90: S | F90: Solo 2 | G90: note | H90: 49 | I90: 2 | J90: 72057594037940625 | K90: N49/C2 | L90: /composition/layers/71/clips/1/connect | M90: 1028 | N90: Button / value | R90: 128 | S90: 0 | T90: APC40 mkII | U90: /composition/layers/71/clips/1/connect | V90: /composition/layers/71/clips/1/connected | W90: /composition/layers/71/clips/1/connected | X90: Connected=1; Connected & previewing=1; Disconnected=0; Empty=0; Off=0; Previewing=0
A91: 87 | B91: 1784313900038 | C91: button_connect | D91: 38 | E91: G6-1 | F91: Grid 1 Track 6 | G91: note | H91: 37 | I91: 1 | J91: 72057594037937552 | K91: N37/C1 | L91: /composition/layers/38/clips/1/connect | M91: 1028 | N91: Button / value | R91: 128 | S91: 0 | T91: APC40 mkII | U91: /composition/layers/38/clips/1/connect | V91: /composition/layers/38/clips/1/connected | W91: /composition/layers/38/clips/1/connected | X91: Connected=0.38582677165354328785; Connected & previewing=0.38582677165354328785; Disconnected=0; Empty=0; Off=0; Previewing=0
A92: 88 | B92: 1784313901144 | C92: wake | D92: 144 | E92: X-FADE | F92: Crossfader | G92: cc | H92: 15 | I92: 1 | J92: 144115188075859888 | K92: CC15/C1 | L92: /composition/layers/144/clips/1/connect | M92: 1028 | N92: CC wake | R92: 128 | S92: 1 | U92: /composition/layers/144/clips/1/connect | X92: Disconnected=1
A93: 89 | B93: 1784313900144 | C93: opacity | D93: 144 | E93: X-FADE | F93: Crossfader | G93: cc | H93: 15 | I93: 1 | J93: 144115188075859888 | K93: CC15/C1 | L93: /composition/layers/144/clips/1/video/opacity | M93: 8 | N93: Absolute | O93: 0.65 | P93: 1 | Q93: ascending | R93: 128 | S93: 1 | U93: /composition/layers/144/clips/1/video/opacity
...

Sheet Continuous Detail
A1: Continuous Controls — Wake + Opacity + Motion
A2: Twenty-seven absolute controls carry three mappings; Tempo is the two-record relative-stepper exception
A4: Layer | B4: Control | C4: MIDI Address | D4: Raw Key | E4: Witness Color | F4: Wake Path | G4: Opacity Path | H4: Opacity Min | I4: Opacity Max | J4: Motion Role | K4: Motion Path | L4: Motion Min | M4: Motion Max | N4: Direction | O4: Behaviour | P4: Mappings | Q4: QA
A5: 94 | B5: FADER1 | C5: CC7/C1 | D5: 144115188075857840 | E5: #e6e6e6ff | F5: /composition/layers/94/clips/1/connect | G5: /composition/layers/94/clips/1/video/opacity | H5: 0.65 | I5: 1 | J5: motion_y | K5: /composition/layers/94/clips/1/video/effects/transform/positiony | L5: 0.50662994 | M5: 0.50429535 | N5: descending | O5: 8 | P5: 3 | Q5: PASS
A6: 95 | B6: FADER2 | C6: CC7/C2 | D6: 144115188075857841 | E6: #e6e6e6ff | F6: /composition/layers/95/clips/1/connect | G6: /composition/layers/95/clips/1/video/opacity | H6: 0.65 | I6: 1 | J6: motion_y | K6: /composition/layers/95/clips/1/video/effects/transform/positiony | L6: 0.50662994 | M6: 0.50429535 | N6: descending | O6: 8 | P6: 3 | Q6: PASS
A7: 96 | B7: FADER3 | C7: CC7/C3 | D7: 144115188075857842 | E7: #e6e6e6ff | F7: /composition/layers/96/clips/1/connect | G7: /composition/layers/96/clips/1/video/opacity | H7: 0.65 | I7: 1 | J7: motion_y | K7: /composition/layers/96/clips/1/video/effects/transform/positiony | L7: 0.50662994 | M7: 0.50429535 | N7: descending | O7: 8 | P7: 3 | Q7: PASS
A8: 97 | B8: FADER4 | C8: CC7/C4 | D8: 144115188075857843 | E8: #e6e6e6ff | F8: /composition/layers/97/clips/1/connect | G8: /composition/layers/97/clips/1/video/opacity | H8: 0.65 | I8: 1 | J8: motion_y | K8: /composition/layers/97/clips/1/video/effects/transform/positiony | L8: 0.50662994 | M8: 0.50429535 | N8: descending | O8: 8 | P8: 3 | Q8: PASS
A9: 98 | B9: FADER5 | C9: CC7/C5 | D9: 144115188075857844 | E9: #e6e6e6ff | F9: /composition/layers/98/clips/1/connect | G9: /composition/layers/98/clips/1/video/opacity | H9: 0.65 | I9: 1 | J9: motion_y | K9: /composition/layers/98/clips/1/video/effects/transform/positiony | L9: 0.50662994 | M9: 0.50429535 | N9: descending | O9: 8 | P9: 3 | Q9: PASS
A10: 99 | B10: FADER6 | C10: CC7/C6 | D10: 144115188075857845 | E10: #e6e6e6ff | F10: /composition/layers/99/clips/1/connect | G10: /composition/layers/99/clips/1/video/opacity | H10: 0.65 | I10: 1 | J10: motion_y | K10: /composition/layers/99/clips/1/video/effects/transform/positiony | L10: 0.50662994 | M10: 0.50429535 | N10: descending | O10: 8 | P10: 3 | Q10: PASS
A11: 100 | B11: FADER7 | C11: CC7/C7 | D11: 144115188075857846 | E11: #e6e6e6ff | F11: /composition/layers/100/clips/1/connect | G11: /composition/layers/100/clips/1/video/opacity | H11: 0.65 | I11: 1 | J11: motion_y | K11: /composition/layers/100/clips/1/video/effects/transform/positiony | L11: 0.50662994 | M11: 0.50429535 | N11: descending | O11: 8 | P11: 3 | Q11: PASS
A12: 101 | B12: FADER8 | C12: CC7/C8 | D12: 144115188075857847 | E12: #e6e6e6ff | F12: /composition/layers/101/clips/1/connect | G12: /composition/layers/101/clips/1/video/opacity | H12: 0.65 | I12: 1 | J12: motion_y | K12: /composition/layers/101/clips/1/video/effects/transform/positiony | L12: 0.50662994 | M12: 0.50429535 | N12: descending | O12: 8 | P12: 3 | Q12: PASS
A13: 102 | B13: TRACK1 | C13: CC48/C1 | D13: 144115188075868336 | E13: #e6e6e6ff | F13: /composition/layers/102/clips/1/connect | G13: /composition/layers/102/clips/1/video/opacity | H13: 0.35 | I13: 1 | J13: motion_rotation | K13: /composition/layers/102/clips/1/video/effects/transform/rotationz | L13: 0.125 | M13: 0.875 | N13: ascending | O13: 8 | P13: 3 | Q13: PASS
A14: 103 | B14: TRACK2 | C14: CC49/C1 | D14: 144115188075868592 | E14: #e6e6e6ff | F14: /composition/layers/103/clips/1/connect | G14: /composition/layers/103/clips/1/video/opacity | H14: 0.35 | I14: 1 | J14: motion_rotation | K14: /composition/layers/103/clips/1/video/effects/transform/rotationz | L14: 0.125 | M14: 0.875 | N14: ascending | O14: 8 | P14: 3 | Q14: PASS
A15: 104 | B15: TRACK3 | C15: CC50/C1 | D15: 144115188075868848 | E15: #e6e6e6ff | F15: /composition/layers/104/clips/1/connect | G15: /composition/layers/104/clips/1/video/opacity | H15: 0.35 | I15: 1 | J15: motion_rotation | K15: /composition/layers/104/clips/1/video/effects/transform/rotationz | L15: 0.125 | M15: 0.875 | N15: ascending | O15: 8 | P15: 3 | Q15: PASS
A16: 105 | B16: TRACK4 | C16: CC51/C1 | D16: 144115188075869104 | E16: #e6e6e6ff | F16: /composition/layers/105/clips/1/connect | G16: /composition/layers/105/clips/1/video/opacity | H16: 0.35 | I16: 1 | J16: motion_rotation | K16: /composition/layers/105/clips/1/video/effects/transform/rotationz | L16: 0.125 | M16: 0.875 | N16: ascending | O16: 8 | P16: 3 | Q16: PASS
... A31: 145 | B31: CUE | C31: CC47/C1 | D31: 144115188075868080 | E31: #e6e6e6ff | F31: /composition/layers/145/clips/1/connect | G31: /composition/layers/145/clips/1/video/opacity | H31: 0.35 | I31: 1 | J31: motion_rotation | K31: /composition/layers/145/clips/1/video/effects/transform/rotationz | L31: 0.125 | M31: 0.875 | N31: ascending | O31: 8 | P31: 3 | Q31: PASS
A32: 148 | B32: TEMPO | C32: CC13/C1 | D32: 144115188075859376 | E32: #e23b3bff | F32: /composition/layers/148/clips/1/connect | J32: tempo_motion | K32: /composition/layers/148/clips/1/video/effects/transform/rotationz | N32: relative | O32: 16392 | P32: 2 | Q32: PASS

Sheet Button Feedback
A1: Button and LED Feedback — 120 Protected Records
A2: Every note mapping preserves the accepted output device, feedback sibling, LED value, and witness color
A4: Layer | B4: Control | C4: Section | D4: MIDI Address | E4: Raw Key | F4: Connect Path | G4: Output Path | H4: Feedback Sibling | I4: Output Device | J4: LED Velocity | K4: Witness Color | L4: Connected Value | M4: Mappings | N4: QA
A5: 1 | B5: G1-5 | C5: grid | D5: N0/C1 | E5: 72057594037928080 | F5: /composition/layers/1/clips/1/connect | G5: /composition/layers/1/clips/1/connect | H5: /composition/layers/1/clips/1/connected | I5: APC40 mkII | J5: 45 | K5: #2b5bffff | L5: 0.35433071 | M5: 1 | N5: PASS
A6: 2 | B6: G2-5 | C6: grid | D6: N1/C1 | E6: 72057594037928336 | F6: /composition/layers/2/clips/1/connect | G6: /composition/layers/2/clips/1/connect | H6: /composition/layers/2/clips/1/connected | I6: APC40 mkII | J6: 37 | K6: #17c8e8ff | L6: 0.29133858 | M6: 1 | N6: PASS
A7: 3 | B7: G3-5 | C7: grid | D7: N2/C1 | E7: 72057594037928592 | F7: /composition/layers/3/clips/1/connect | G7: /composition/layers/3/clips/1/connect | H7: /composition/layers/3/clips/1/connected | I7: APC40 mkII | J7: 21 | K7: #23c552ff | L7: 0.16535433 | M7: 1 | N7: PASS
A8: 4 | B8: G4-5 | C8: grid | D8: N3/C1 | E8: 72057594037928848 | F8: /composition/layers/4/clips/1/connect | G8: /composition/layers/4/clips/1/connect | H8: /composition/layers/4/clips/1/connected | I8: APC40 mkII | J8: 5 | K8: #e23b3bff | L8: 0.039370079 | M8: 1 | N8: PASS
A9: 5 | B9: G5-5 | C9: grid | D9: N4/C1 | E9: 72057594037929104 | F9: /composition/layers/5/clips/1/connect | G9: /composition/layers/5/clips/1/connect | H9: /composition/layers/5/clips/1/connected | I9: APC40 mkII | J9: 9 | K9: #f08a24ff | L9: 0.070866142 | M9: 1 | N9: PASS
A10: 6 | B10: G6-5 | C10: grid | D10: N5/C1 | E10: 72057594037929360 | F10: /composition/layers/6/clips/1/connect | G10: /composition/layers/6/clips/1/connect | H10: /composition/layers/6/clips/1/connected | I10: APC40 mkII | J10: 49 | K10: #7a3fc0ff | L10: 0.38582677 | M10: 1 | N10: PASS
A11: 7 | B11: G7-5 | C11: grid | D11: N6/C1 | E11: 72057594037929616 | F11: /composition/layers/7/clips/1/connect | G11: /composition/layers/7/clips/1/connect | H11: /composition/layers/7/clips/1/connected | I11: APC40 mkII | J11: 53 | K11: #c81e9aff | L11: 0.41732283 | M11: 1 | N11: PASS
A12: 8 | B12: G8-5 | C12: grid | D12: N7/C1 | E12: 72057594037929872 | F12: /composition/layers/8/clips/1/connect | G12: /composition/layers/8/clips/1/connect | H12: /composition/layers/8/clips/1/connected | I12: APC40 mkII | J12: 3 | K12: #e6e6e6ff | L12: 0.023622047 | M12: 1 | N12: PASS
A13: 9 | B13: G1-4 | C13: grid | D13: N8/C1 | E13: 72057594037930128 | F13: /composition/layers/9/clips/1/connect | G13: /composition/layers/9/clips/1/connect | H13: /composition/layers/9/clips/1/connected | I13: APC40 mkII | J13: 45 | K13: #2b5bffff | L13: 0.35433071 | M13: 1 | N13: PASS
A14: 10 | B14: G2-4 | C14: grid | D14: N9/C1 | E14: 72057594037930384 | F14: /composition/layers/10/clips/1/connect | G14: /composition/layers/10/clips/1/connect | H14: /composition/layers/10/clips/1/connected | I14: APC40 mkII | J14: 37 | K14: #17c8e8ff | L14: 0.29133858 | M14: 1 | N14: PASS
A15: 11 | B15: G3-4 | C15: grid | D15: N10/C1 | E15: 72057594037930640 | F15: /composition/layers/11/clips/1/connect | G15: /composition/layers/11/clips/1/connect | H15: /composition/layers/11/clips/1/connected | I15: APC40 mkII | J15: 21 | K15: #23c552ff | L15: 0.16535433 | M15: 1 | N15: PASS
A16: 12 | B16: G4-4 | C16: grid | D16: N11/C1 | E16: 72057594037930896 | F16: /composition/layers/12/clips/1/connect | G16: /composition/layers/12/clips/1/connect | H16: /composition/layers/12/clips/1/connected | I16: APC40 mkII | J16: 5 | K16: #e23b3bff | L16: 0.039370079 | M16: 1 | N16: PASS
... A124: 147 | B124: BANKLCK | C124: navigation | D124: N103/C1 | E124: 72057594037954448 | F124: /composition/layers/147/clips/1/connect | G124: /composition/layers/147/clips/1/connect | H124: /composition/layers/147/clips/1/connected | I124: APC40 mkII | J124: 49 | K124: #f08a24ff | L124: 0.38582677 | M124: 1 | N124: PASS

Sheet QA Checks
A1: Verification Checklist — Accepted B1 Contract
A2: Actual values are formula-driven from the workbook tables; green means the exported workbook reconciles to the installed XML
A4: # | B4: Check | C4: Expected | D4: Actual | E4: Status
A5: 1 | B5: Source XML SHA-256 | C5: 4628634b4fb9a9909a5b1ee9d7c9df1a759371cc7a90ce183d8bb4cc40d1abc5 | D5: 4628634b4fb9a9909a5b1ee9d7c9df1a759371cc7a90ce183d8bb4cc40d1abc5 | E5: =IF(C5=D5,"PASS","FAIL")
A6: 2 | B6: Physical control rows | C6: 148 | D6: =COUNTA('Control Map'!$A$5:$A$152) | E6: =IF(C6=D6,"PASS","FAIL")
A7: 3 | B7: XML shortcut records | C7: 203 | D7: =COUNTA('XML Shortcuts'!$B$5:$B$207) | E7: =IF(C7=D7,"PASS","FAIL")
A8: 4 | B8: Unique shortcut IDs | C8: 203 | D8: =ROWS(_xlfn.UNIQUE('XML Shortcuts'!$B$5:$B$207)) | E8: =IF(C8=D8,"PASS","FAIL")
A9: 5 | B9: Unique raw MIDI keys | C9: 148 | D9: =ROWS(_xlfn.UNIQUE('XML Shortcuts'!$J$5:$J$207)) | E9: =IF(C9=D9,"PASS","FAIL")
A10: 6 | B10: Button / note controls | C10: 120 | D10: =COUNTIF('Control Map'!$E$5:$E$152,"note") | E10: =IF(C10=D10,"PASS","FAIL")
A11: 7 | B11: Continuous / CC controls | C11: 28 | D11: =COUNTIF('Control Map'!$E$5:$E$152,"cc") | E11: =IF(C11=D11,"PASS","FAIL")
A12: 8 | B12: Button connect mappings | C12: 120 | D12: =COUNTIF('XML Shortcuts'!$C$5:$C$207,"button_connect") | E12: =IF(C12=D12,"PASS","FAIL")
A13: 9 | B13: CC wake mappings | C13: 28 | D13: =COUNTIF('XML Shortcuts'!$C$5:$C$207,"wake") | E13: =IF(C13=D13,"PASS","FAIL")
A14: 10 | B14: Opacity mappings | C14: 27 | D14: =COUNTIF('XML Shortcuts'!$C$5:$C$207,"opacity") | E14: =IF(C14=D14,"PASS","FAIL")
A15: 11 | B15: Position Y mappings | C15: 9 | D15: =COUNTIF('XML Shortcuts'!$C$5:$C$207,"motion_y") | E15: =IF(C15=D15,"PASS","FAIL")
A16: 12 | B16: Position X mappings | C16: 1 | D16: =COUNTIF('XML Shortcuts'!$C$5:$C$207,"motion_x") | E16: =IF(C16=D16,"PASS","FAIL")
A17: 13 | B17: Rotation Z mappings (absolute + Tempo) | C17: 18 | D17: =COUNTIF('XML Shortcuts'!$C$5:$C$207,"motion_rotation")+COUNTIF('XML Shortcuts'!$C$5:$C$207,"tempo_motion") | E17: =IF(C17=D17,"PASS","FAIL")
A18: 14 | B18: Delay mappings | C18: 0 | D18: =COUNTIF('XML Shortcuts'!$C$5:$C$207,"delay") | E18: =IF(C18=D18,"PASS","FAIL")
A19: 15 | B19: Button records with output device | C19: 120 | D19: =COUNTIFS('XML Shortcuts'!$G$5:$G$207,"note",'XML Shortcuts'!$T$5:$T$207,"APC40 mkII") | E19: =IF(C19=D19,"PASS","FAIL")
A20: 16 | B20: CC records with output device | C20: 0 | D20: =COUNTIFS('XML Shortcuts'!$G$5:$G$207,"cc",'XML Shortcuts'!$T$5:$T$207,"APC40 mkII") | E20: =IF(C20=D20,"PASS","FAIL")
